#VRML_SIM R2020a utf8
WorldInfo {
  CFM 1e-08
}
Viewpoint {
  orientation 0.2248900869461508 -0.9602992366684373 -0.16507520966931816 5.015750919154296
  position 1.1416151622910158 0.5925803265045854 0.4484395809639163
}
TexturedBackground {
}
TexturedBackgroundLight {
}
Floor {
  size 100 100
}
Robot {
  translation 1.88292e-07 0.187739 0.0273197
  rotation 0.26470003707322803 -0.9272911298740865 0.26469803707294787 -1.6462153071795864
  children [
    DEF accelerometer Accelerometer {
      name "ACCELEROMETER"
    }
    DEF compass Compass {
      name "COMPASS"
    }
    DEF GYRO Gyro {
      name "GYRO"
    }
    DEF IMU InertialUnit {
      name "IMU"
    }
    DEF MOTOR1 HingeJoint {
      jointParameters HingeJointParameters {
        position -5.453140635723079
        axis 0 0 1
        anchor 0 -0.1 0.07
      }
      device [
        PositionSensor {
          name "POS1"
        }
        DEF MOTOR1 RotationalMotor {
          name "MOTOR1"
          maxVelocity 100
          maxTorque 100
        }
      ]
      endPoint DEF WHEEL1 Solid {
        translation 4.0430042854528897e-05 -0.09996536906853552 0.06999999999900207
        rotation 0.6621283158253346 0.5299000667884058 0.5298981153013745 1.971887897284384
        children [
          DEF WHEEL1 Shape {
            appearance PBRAppearance {
            }
            geometry Cylinder {
              height 0.03
              radius 0.1
            }
          }
        ]
        name "WHEEL1"
        boundingObject USE WHEEL1
        physics Physics {
          density -1
          mass 0.01
        }
      }
    }
    DEF MOTOR2 HingeJoint {
      jointParameters HingeJointParameters {
        position -5.453139575454807
        axis 0 0 1
        anchor 0 -0.1 -0.07
      }
      device [
        PositionSensor {
          name "POS2"
        }
        DEF MOTOR2 RotationalMotor {
          name "MOTOR2"
          maxVelocity 100
          maxTorque 100
        }
      ]
      endPoint DEF WHEEL2 Solid {
        translation 6.74094003673357e-05 -0.09997069532993452 -0.06999999999537941
        rotation 0.7592925117887399 0.46015180318681803 0.46014693258291545 1.84275508240437
        children [
          DEF WHEEL1 Shape {
            appearance PBRAppearance {
            }
            geometry Cylinder {
              height 0.03
              radius 0.1
            }
          }
        ]
        name "wheel2"
        boundingObject USE WHEEL1
        physics Physics {
          density -1
          mass 0.01
        }
      }
    }
    DEF BODE Shape {
      appearance PBRAppearance {
      }
      geometry Box {
        size 0.1 0.2 0.1
      }
    }
  ]
  boundingObject USE BODE
  physics Physics {
    density -1
    mass 1
  }
  controller "key_pid_control"
}
